Traceback (most recent call last):
  File "./server.py", line 38, in <module>
    httpd = ServerClass(server_address, HandlerClass)
  File "/System/Library/Frameworks/Python.framework/Versions/2.7/lib/python2.7/SocketServer.py", line 420, in __init__
    self.server_bind()
  File "/System/Library/Frameworks/Python.framework/Versions/2.7/lib/python2.7/BaseHTTPServer.py", line 108, in server_bind
    SocketServer.TCPServer.server_bind(self)
  File "/System/Library/Frameworks/Python.framework/Versions/2.7/lib/python2.7/SocketServer.py", line 434, in server_bind
    self.socket.bind(self.server_address)
  File "/System/Library/Frameworks/Python.framework/Versions/2.7/lib/python2.7/socket.py", line 228, in meth
    return getattr(self._sock,name)(*args)
socket.error: [Errno 48] Address already in use
Traceback (most recent call last):
  File "./server.py", line 38, in <module>
    httpd = ServerClass(server_address, HandlerClass)
  File "/System/Library/Frameworks/Python.framework/Versions/2.7/lib/python2.7/SocketServer.py", line 420, in __init__
    self.server_bind()
  File "/System/Library/Frameworks/Python.framework/Versions/2.7/lib/python2.7/BaseHTTPServer.py", line 108, in server_bind
    SocketServer.TCPServer.server_bind(self)
  File "/System/Library/Frameworks/Python.framework/Versions/2.7/lib/python2.7/SocketServer.py", line 434, in server_bind
    self.socket.bind(self.server_address)
  File "/System/Library/Frameworks/Python.framework/Versions/2.7/lib/python2.7/socket.py", line 228, in meth
    return getattr(self._sock,name)(*args)
socket.error: [Errno 48] Address already in use
Traceback (most recent call last):
  File "./server.py", line 38, in <module>
    httpd = ServerClass(server_address, HandlerClass)
  File "/System/Library/Frameworks/Python.framework/Versions/2.7/lib/python2.7/SocketServer.py", line 420, in __init__
    self.server_bind()
  File "/System/Library/Frameworks/Python.framework/Versions/2.7/lib/python2.7/BaseHTTPServer.py", line 108, in server_bind
    SocketServer.TCPServer.server_bind(self)
  File "/System/Library/Frameworks/Python.framework/Versions/2.7/lib/python2.7/SocketServer.py", line 434, in server_bind
    self.socket.bind(self.server_address)
  File "/System/Library/Frameworks/Python.framework/Versions/2.7/lib/python2.7/socket.py", line 228, in meth
    return getattr(self._sock,name)(*args)
socket.error: [Errno 48] Address already in use
Traceback (most recent call last):
  File "./server.py", line 33, in <module>
    httpd = ServerClass(server_address, HandlerClass)
  File "/System/Library/Frameworks/Python.framework/Versions/2.7/lib/python2.7/SocketServer.py", line 420, in __init__
    self.server_bind()
  File "/System/Library/Frameworks/Python.framework/Versions/2.7/lib/python2.7/BaseHTTPServer.py", line 108, in server_bind
    SocketServer.TCPServer.server_bind(self)
  File "/System/Library/Frameworks/Python.framework/Versions/2.7/lib/python2.7/SocketServer.py", line 434, in server_bind
    self.socket.bind(self.server_address)
  File "/System/Library/Frameworks/Python.framework/Versions/2.7/lib/python2.7/socket.py", line 228, in meth
    return getattr(self._sock,name)(*args)
socket.error: [Errno 48] Address already in use
Traceback (most recent call last):
  File "./server.py", line 33, in <module>
    httpd = ServerClass(server_address, HandlerClass)
  File "/System/Library/Frameworks/Python.framework/Versions/2.7/lib/python2.7/SocketServer.py", line 420, in __init__
    self.server_bind()
  File "/System/Library/Frameworks/Python.framework/Versions/2.7/lib/python2.7/BaseHTTPServer.py", line 108, in server_bind
    SocketServer.TCPServer.server_bind(self)
  File "/System/Library/Frameworks/Python.framework/Versions/2.7/lib/python2.7/SocketServer.py", line 434, in server_bind
    self.socket.bind(self.server_address)
  File "/System/Library/Frameworks/Python.framework/Versions/2.7/lib/python2.7/socket.py", line 228, in meth
    return getattr(self._sock,name)(*args)
socket.error: [Errno 48] Address already in use
Traceback (most recent call last):
  File "./server.py", line 33, in <module>
    httpd = ServerClass(server_address, HandlerClass)
  File "/System/Library/Frameworks/Python.framework/Versions/2.7/lib/python2.7/SocketServer.py", line 420, in __init__
    self.server_bind()
  File "/System/Library/Frameworks/Python.framework/Versions/2.7/lib/python2.7/BaseHTTPServer.py", line 108, in server_bind
    SocketServer.TCPServer.server_bind(self)
  File "/System/Library/Frameworks/Python.framework/Versions/2.7/lib/python2.7/SocketServer.py", line 434, in server_bind
    self.socket.bind(self.server_address)
  File "/System/Library/Frameworks/Python.framework/Versions/2.7/lib/python2.7/socket.py", line 228, in meth
    return getattr(self._sock,name)(*args)
socket.error: [Errno 48] Address already in use
Traceback (most recent call last):
  File "./server.py", line 33, in <module>
    httpd = ServerClass(server_address, HandlerClass)
  File "/System/Library/Frameworks/Python.framework/Versions/2.7/lib/python2.7/SocketServer.py", line 420, in __init__
    self.server_bind()
  File "/System/Library/Frameworks/Python.framework/Versions/2.7/lib/python2.7/BaseHTTPServer.py", line 108, in server_bind
    SocketServer.TCPServer.server_bind(self)
  File "/System/Library/Frameworks/Python.framework/Versions/2.7/lib/python2.7/SocketServer.py", line 434, in server_bind
    self.socket.bind(self.server_address)
  File "/System/Library/Frameworks/Python.framework/Versions/2.7/lib/python2.7/socket.py", line 228, in meth
    return getattr(self._sock,name)(*args)
socket.error: [Errno 48] Address already in use
Traceback (most recent call last):
  File "/System/Library/Frameworks/Python.framework/Versions/2.7/lib/python2.7/SocketServer.py", line 295, in _handle_request_noblock
    self.process_request(request, client_address)
  File "/System/Library/Frameworks/Python.framework/Versions/2.7/lib/python2.7/SocketServer.py", line 321, in process_request
    self.finish_request(request, client_address)
  File "/System/Library/Frameworks/Python.framework/Versions/2.7/lib/python2.7/SocketServer.py", line 334, in finish_request
    self.RequestHandlerClass(request, client_address, self)
  File "/System/Library/Frameworks/Python.framework/Versions/2.7/lib/python2.7/SocketServer.py", line 655, in __init__
    self.handle()
  File "/System/Library/Frameworks/Python.framework/Versions/2.7/lib/python2.7/BaseHTTPServer.py", line 340, in handle
    self.handle_one_request()
  File "/System/Library/Frameworks/Python.framework/Versions/2.7/lib/python2.7/BaseHTTPServer.py", line 310, in handle_one_request
    self.raw_requestline = self.rfile.readline(65537)
  File "/System/Library/Frameworks/Python.framework/Versions/2.7/lib/python2.7/socket.py", line 480, in readline
    data = self._sock.recv(self._rbufsize)
error: [Errno 35] Resource temporarily unavailable
----------------------------------------
Exception happened during processing of request from ('127.0.0.1', 53856)
----------------------------------------
Traceback (most recent call last):
  File "/System/Library/Frameworks/Python.framework/Versions/2.7/lib/python2.7/SocketServer.py", line 295, in _handle_request_noblock
    self.process_request(request, client_address)
  File "/System/Library/Frameworks/Python.framework/Versions/2.7/lib/python2.7/SocketServer.py", line 321, in process_request
    self.finish_request(request, client_address)
  File "/System/Library/Frameworks/Python.framework/Versions/2.7/lib/python2.7/SocketServer.py", line 334, in finish_request
    self.RequestHandlerClass(request, client_address, self)
  File "/System/Library/Frameworks/Python.framework/Versions/2.7/lib/python2.7/SocketServer.py", line 655, in __init__
    self.handle()
  File "/System/Library/Frameworks/Python.framework/Versions/2.7/lib/python2.7/BaseHTTPServer.py", line 340, in handle
    self.handle_one_request()
  File "/System/Library/Frameworks/Python.framework/Versions/2.7/lib/python2.7/BaseHTTPServer.py", line 310, in handle_one_request
    self.raw_requestline = self.rfile.readline(65537)
  File "/System/Library/Frameworks/Python.framework/Versions/2.7/lib/python2.7/socket.py", line 480, in readline
    data = self._sock.recv(self._rbufsize)
error: [Errno 35] Resource temporarily unavailable
----------------------------------------
Exception happened during processing of request from ('127.0.0.1', 53912)
----------------------------------------
Traceback (most recent call last):
  File "./server.py", line 35, in <module>
    httpd.handle_request()
  File "/System/Library/Frameworks/Python.framework/Versions/2.7/lib/python2.7/SocketServer.py", line 276, in handle_request
    fd_sets = _eintr_retry(select.select, [self], [], [], timeout)
  File "/System/Library/Frameworks/Python.framework/Versions/2.7/lib/python2.7/SocketServer.py", line 156, in _eintr_retry
    except (OSError, select.error) as e:
KeyboardInterrupt
Traceback (most recent call last):
  File "/System/Library/Frameworks/Python.framework/Versions/2.7/lib/python2.7/SocketServer.py", line 295, in _handle_request_noblock
    self.process_request(request, client_address)
  File "/System/Library/Frameworks/Python.framework/Versions/2.7/lib/python2.7/SocketServer.py", line 321, in process_request
    self.finish_request(request, client_address)
  File "/System/Library/Frameworks/Python.framework/Versions/2.7/lib/python2.7/SocketServer.py", line 334, in finish_request
    self.RequestHandlerClass(request, client_address, self)
  File "/System/Library/Frameworks/Python.framework/Versions/2.7/lib/python2.7/SocketServer.py", line 655, in __init__
    self.handle()
  File "/System/Library/Frameworks/Python.framework/Versions/2.7/lib/python2.7/BaseHTTPServer.py", line 340, in handle
    self.handle_one_request()
  File "/System/Library/Frameworks/Python.framework/Versions/2.7/lib/python2.7/BaseHTTPServer.py", line 310, in handle_one_request
    self.raw_requestline = self.rfile.readline(65537)
  File "/System/Library/Frameworks/Python.framework/Versions/2.7/lib/python2.7/socket.py", line 480, in readline
    data = self._sock.recv(self._rbufsize)
error: [Errno 35] Resource temporarily unavailable
hello
----------------------------------------
Exception happened during processing of request from ('127.0.0.1', 53943)
----------------------------------------
17:31:38 workflow.py:1814 DEBUG    Cached data saved at : /Users/Zai/Library/Caches/com.runningwithcrayons.Alfred-2/Workflow Data/com.drive.azai91/drive_request_token.cpickle
